File: PPMS_Curie-Weiss/exampleData.dat
[Header]
; ACMS Data File (default extension .dat)
; Copyright 1999, Quantum Design, Inc. All rights reserved.
TITLE,Arbitrary Example
FILEOPENTIME,2101535.23,01/25/2013,9:47 am
BYAPP,ACMS,1.0,1.1
INFO,PPMS ACMS Option Version: 1.0.9 Build 14,APPNAME
INFO,HARMONICS,1
INFO,mass,Arbitrary
INFO,Identity,Example
INFO,,
INFO,,
INFO,,
INFO,,
INFO,,
INFO,,
INFO,,
INFO,,
DATATYPE,COMMENT,1
DATATYPE,TIME,2
FIELDGROUP,AC Mag,2,3,4,5,6,8,9,10,11,12
FIELDGROUP,DC Mag,2,3,4,7,8
STARTUPGROUP,All
STARTUPAXIS,X,2,LINEAR,AUTO
TIMEMODE,MINUTES,RELATIVE
PLOT_APPEARANCE,ALL,HORZ_GRID_ON,VERT_GRID_ON,MARKERS_AND_LINES
RECORDS,ALL_RECORDS
DATATYPE,TIME,2
DATATYPE,COMMENT,1
[Data]
Comment,Time Stamp (sec),Temperature (K),Magnetic Field (Oe),Frequency (Hz),Amplitude (Oe),M-DC (emu),M-Std.Dev. (emu),M' (emu),M'' (emu),Moment (emu),Phase (deg),Calcoil' (emu),Calcoil'' (emu),Calcoil (emu),CC Phase (deg),Count,Gain,Measure Type,Elapsed (sec),Sample Center (cm),Max.Signal (V),PPMS Status (code),DSP Status (code),Min.Temperature (K),Max.Temperature (K),Min.Field (Oe),Max.Field (Oe),DC Position (cm),PPMS Temperature (K),PPMS Position,Bridge 1 Resistance (ohms),Bridge 1 Excitation (uA),Bridge 2 Resistance (ohms),Bridge 2 Excitation (uA),Bridge 3 Resistance (ohms),Bridge 3 Excitation (uA),Bridge 4 Resistance (ohms),Bridge 4 Excitation (uA),Signal 1 Vin (V),Signal 2 Vin (V),Digital Inputs (code),Drive 1 Iout (mA),Drive 1 Ipower (watts),Drive 2 Iout (mA),Drive 2 Ipower (watts),Pressure (),Map 20 (),Map 21 (),Map 22 (),Map 23 (),Map 24 (),Map 25 (),Map 26 (),Map 27 (),Map 28 (),Map 29 ()
,2116401.96,1.9909227,9999.475,,,0.00605192636870323,9.17086491724639E-5,,,,,,,,,5,125,0,19.78100000415,0.158117602128942,6.40094497186619E-5,4374,0,1.9778304,2.004015,9999.475,9999.475,0.158117602128942,1.99255,,,,,,,,,,,,,,,,,,,,,,,1.9909227
,2116430.42,1.98819885,9999.475,,,0.00609197306327777,4.08773071500954E-5,,,,,,,,,5,125,0,21.2179999798536,0.120976676442249,6.45865257186859E-5,4373,0,1.9821904,1.9942073,9999.475,9999.475,0.120976676442249,1.99025,,,,,,,,,,,,,,,,,,,,,,,1.98819885
,2116458.67,1.9924943,9999.475,,,0.00608182775691005,4.29562605926266E-5,,,,,,,,,5,125,0,21.718000411056,0.0755307589122187,6.51945473759911E-5,4373,0,1.9904859,1.9945027,9999.475,9999.475,0.0755307589122187,1.9935,,,,,,,,,,,,,,,,,,,,,,,1.9924943
,2116597.94,2.02448715,9999.475,,,0.00606108101928521,4.1494614518398E-5,,,,,,,,,5,125,0,7.00000037904829,0.0755307589122187,6.27014338360431E-5,4370,0,2.0008013,2.048173,9999.475,9999.475,0.0709251560740836,2.03035,,,,,,,,,,,,,,,,,,,,,,,2.02448715
,2116721.92,3.0330738,9999.475,,,0.00583956626075758,4.15081024730216E-5,,,,,,,,,5,125,0,6.49999994784594,0.0755307589122187,6.20928935364372E-5,4370,0,3.0102823,3.0558653,9999.475,9999.475,0.064898773315306,3.03905,,,,,,,,,,,,,,,,,,,,,,,3.0330738
,2116845.12,4.0395155,9999.475,,,0.00566180807703783,4.1574983997418E-5,,,,,,,,,5,125,0,6.71900021843612,0.0755307589122187,6.11659068641397E-5,4370,0,4.0112262,4.0678048,9999.475,9999.475,0.0680638156499465,4.0497,,,,,,,,,,,,,,,,,,,,,,,4.0395155
,2116967.27,5.04197335,9999.475,,,0.00546633548320907,4.28454839359832E-5,,,,,,,,,5,125,0,6.98400016408414,0.0755307589122187,6.08797891948648E-5,4370,0,5.0136652,5.0702815,9999.475,9999.475,0.0695767624356821,5.0567,,,,,,,,,,,,,,,,,,,,,,,5.04197335
,2117088.57,6.04438115,9999.475,,,0.00531306942201404,4.26445860536055E-5,,,,,,,,,5,125,0,6.79700032342225,0.0755307589122187,6.08037216574141E-5,4370,0,6.0194602,6.0693021,9999.475,9999.475,0.0558031009210375,6.05505,,,,,,,,,,,,,,,,,,,,,,,6.04438115
,2117208.53,7.0451498,9999.475,,,0.00518390378430818,4.28303326550846E-5,,,,,,,,,5,125,0,7.13999974541366,0.0755307589122187,6.0400909470459E-5,4370,0,7.014729,7.0755706,9999.475,9999.475,0.0585737157816084,7.04915,,,,,,,,,,,,,,,,,,,,,,,7.0451498
,2117328.12,8.03378535,9999.475,,,0.00503849761372808,4.37903384191453E-5,,,,,,,,,5,125,0,6.96799994911998,0.0755307589122187,6.00401073098688E-5,4370,0,8.0132809,8.0542898,9999.475,9999.475,0.0599589826537576,8.0413,,,,,,,,,,,,,,,,,,,,,,,8.03378535
,2117449.86,9.04456565,9999.475,,,0.00493230692632913,4.33825962611269E-5,,,,,,,,,5,125,0,7.07800048403442,0.0755307589122187,5.93769366879119E-5,4370,0,9.0141582,9.0749731,9999.475,9999.475,0.0617330467787496,9.04675,,,,,,,,,,,,,,,,,,,,,,,9.04456565
,2117570.63,10.0417771,9999.475,,,0.00484973015430452,4.43080088080983E-5,,,,,,,,,5,125,0,6.92199964541942,0.0755307589122187,5.90118125081483E-5,4370,0,10.0093231,10.0742311,9999.475,9999.475,0.0628091454886642,10.05365,,,,,,,,,,,,,,,,,,,,,,,10.0417771
,2117690.20,11.03940485,9999.475,,,0.00475393418436386,4.38511530744536E-5,,,,,,,,,5,125,0,6.48399973288178,0.0755307589122187,5.87175694428275E-5,4370,0,11.01336,11.0654497,9999.475,9999.475,0.0634733070240751,11.0426,,,,,,,,,,,,,,,,,,,,,,,11.03940485
,2117812.41,12.04469825,9999.475,,,0.0046763092957125,4.40420690251797E-5,,,,,,,,,5,125,0,7.03100000973791,0.0755307589122187,5.88104064146708E-5,4370,0,12.0169487,12.0724478,9999.475,9999.475,0.0582727069717309,12.06695,,,,,,,,,,,,,,,,,,,,,,,12.04469825
,2117932.13,13.04526755,9999.475,,,0.00461864521362861,4.47479549902978E-5,,,,,,,,,5,125,0,6.92199964541942,0.0755307589122187,5.84791668652262E-5,4370,0,13.0146093,13.0759258,9999.475,9999.475,0.0596828310005238,13.05415,,,,,,,,,,,,,,,,,,,,,,,13.04526755
,2118051.71,14.03891325,9999.475,,,0.00456444380969316,4.45333529050062E-5,,,,,,,,,5,125,0,6.93800048902631,0.0755307589122187,5.83059403367588E-5,4370,0,14.009738,14.0680885,9999.475,9999.475,0.061645265016231,14.0542,,,,,,,,,,,,,,,,,,,,,,,14.03891325
,2118172.44,15.03521635,9999.475,,,0.00453188363624539,4.51283326817159E-5,,,,,,,,,5,125,0,6.73499980475754,0.0755307589122187,5.82680794488004E-5,4370,0,15.0059319,15.0645008,9999.475,9999.475,0.0576665340094867,15.05895,,,,,,,,,,,,,,,,,,,,,,,15.03521635
,2118292.97,16.03968715,9999.475,,,0.00447200997541847,4.34899981425956E-5,,,,,,,,,5,125,0,6.46800014656037,0.0755307589122187,5.81050528855821E-5,4370,0,16.0099144,16.0694599,9999.475,9999.475,0.0564010784825331,16.06575,,,,,,,,,,,,,,,,,,,,,,,16.03968715
,2118414.25,17.04463675,9999.475,,,0.00443068803495877,4.53942852034394E-5,,,,,,,,,5,125,0,6.76499989349395,0.0755307589122187,5.75203448078221E-5,4370,0,17.0112381,17.0780354,9999.475,9999.475,0.0675144149715929,17.06375,,,,,,,,,,,,,,,,,,,,,,,17.04463675
,2118533.93,18.0407076,9999.475,,,0.00436904348830042,4.49425660137028E-5,,,,,,,,,5,125,0,7.15599996037781,0.0755307589122187,5.75904959439956E-5,4370,0,18.0120106,18.0694046,9999.475,9999.475,0.0604450828620219,18.05975,,,,,,,,,,,,,,,,,,,,,,,18.0407076
,2118654.74,19.0448666,9999.475,,,0.00428865828407036,4.62309793545082E-5,,,,,,,,,5,125,0,7.00000037904829,0.0755307589122187,5.78630397191276E-5,4370,0,19.014782,19.0749512,9999.475,9999.475,0.0479064738048611,19.07135,,,,,,,,,,,,,,,,,,,,,,,19.0448666
,2118774.38,20.0308609,9999.475,,,0.00424259813969323,4.89921532177265E-5,,,,,,,,,5,125,0,6.73499980475754,0.0755307589122187,5.8576052803184E-5,4370,0,20.0118008,20.049921,9999.475,9999.475,0.0250791748776453,20.0384,,,,,,,,,,,,,,,,,,,,,,,20.0308609
,2119068.42,25.0127115,9999.475,,,0.00400247577508438,5.74369470034451E-5,,,,,,,,,5,125,0,6.79700032342225,0.0755307589122187,5.92188918605638E-5,4370,0,25.0048046,25.0206184,9999.475,9999.475,-0.0193797167312219,25.01635,,,,,,,,,,,,,,,,,,,,,,,25.0127115
,2119230.14,30.16001605,9999.475,,,0.00380284993001939,6.36477617335116E-5,,,,,,,,,5,125,0,6.56199983786792,0.0755307589122187,5.92737328387562E-5,4370,0,30.0375404,30.2824917,9999.475,9999.475,-0.0457821438030931,30.59845,,,,,,,,,,,,,,,,,,,,,,,30.16001605
,2119379.80,35.12929535,9999.475,,,0.00363571261663811,6.51850325801171E-5,,,,,,,,,5,125,0,6.92200027406216,0.0755307589122187,5.84607455849463E-5,4370,0,35.0348206,35.2237701,9999.475,9999.475,-0.0479573804687319,35.55125,,,,,,,,,,,,,,,,,,,,,,,35.12929535
,2119531.84,40.16685675,9999.475,,,0.003486956739743,6.47431111861678E-5,,,,,,,,,5,125,0,6.82799995411187,0.0755307589122187,5.71723121597739E-5,4370,0,40.054554,40.2791595,9999.475,9999.475,-0.0488296249347339,40.79975,,,,,,,,,,,,,,,,,,,,,,,40.16685675
,2119685.02,45.15138435,9999.475,,,0.00334774145374335,6.83289309873649E-5,,,,,,,,,5,125,0,6.68699978850782,0.0755307589122187,5.67953407361985E-5,4370,0,45.0384483,45.2643204,9999.475,9999.475,-0.0590725883751012,45.98995,,,,,,,,,,,,,,,,,,,,,,,45.15138435
,2119836.34,50.1440811,9999.475,,,0.00322343140306307,6.50270148325631E-5,,,,,,,,,5,125,0,6.73399963416159,0.0755307589122187,5.60032012061639E-5,4370,0,50.0428505,50.2453117,9999.475,9999.475,-0.0532108626224706,51.108,,,,,,,,,,,,,,,,,,,,,,,50.1440811
,2119989.62,55.16332435,9999.475,,,0.00311240340472149,6.15985718268132E-5,,,,,,,,,5,125,0,6.70300000347197,0.0755307589122187,5.52741359900122E-5,4370,0,55.0543861,55.2722626,9999.475,9999.475,-0.0448318057657818,56.3662,,,,,,,,,,,,,,,,,,,,,,,55.16332435
,2120142.67,60.1719494,9999.475,,,0.00300788045478287,6.17344571653361E-5,,,,,,,,,5,125,0,6.57800005283207,0.0755307589122187,5.45641793856346E-5,4374,0,60.0626602,60.2812386,9999.475,9999.475,-0.0408262174410412,61.62275,,,,,,,,,,,,,,,,,,,,,,,60.1719494
,2120295.28,65.17980955,9999.475,,,0.00292500470983064,6.14675445984478E-5,,,,,,,,,5,125,0,6.62499989848584,0.0755307589122187,5.42748628371191E-5,4374,0,65.0690994,65.2905197,9999.475,9999.475,-0.0469562728527814,66.8187,,,,,,,,,,,,,,,,,,,,,,,65.17980955
,2120447.26,70.14993285,9999.475,,,0.00282778674456235,6.00144793465164E-5,,,,,,,,,5,125,0,6.49999994784594,0.0755307589122187,5.3725312326321E-5,4374,0,70.0352173,70.2646484,9999.475,9999.475,-0.039649849934578,72.04085,,,,,,,,,,,,,,,,,,,,,,,70.14993285
,2120599.42,75.1485634,9999.475,,,0.0027349753967114,5.93209276022729E-5,,,,,,,,,5,125,0,7.04699959605932,0.0755307589122187,5.31024913289554E-5,4374,0,75.0315399,75.2655869,9999.475,9999.475,-0.0359745796491085,77.24085,,,,,,,,,,,,,,,,,,,,,,,75.1485634
,2120752.41,80.16786575,9999.475,,,0.00268233721871838,6.04702506064477E-5,,,,,,,,,5,125,0,7.42200007662177,0.0755307589122187,5.27369740578218E-5,4374,0,80.0487976,80.2869339,9999.475,9999.475,-0.0411737355694923,82.5892,,,,,,,,,,,,,,,,,,,,,,,80.16786575
,2120904.27,85.16324235,9999.475,,,0.00259047428706669,6.16654842457489E-5,,,,,,,,,5,125,0,7.64099971856922,0.0755307589122187,5.23575329154152E-5,4374,0,85.0444031,85.2820816,9999.475,9999.475,-0.0390015680134368,87.7679,,,,,,,,,,,,,,,,,,,,,,,85.16324235
,2121056.64,90.1866188,9999.475,,,0.00251083553532715,6.07087340858458E-5,,,,,,,,,5,125,0,7.29700012598187,0.0755307589122187,5.20111924677814E-5,4374,0,90.0697632,90.3034744,9999.475,9999.475,-0.0396833350621674,93.04265,,,,,,,,,,,,,,,,,,,,,,,90.1866188
,2121207.09,95.1618767,9999.475,,,0.0024501339036401,6.29322860515145E-5,,,,,,,,,5,125,0,6.87499979976565,0.0755307589122187,5.17703124826783E-5,4374,0,95.0473938,95.2763596,9999.475,9999.475,-0.0460706123380847,98.16875,,,,,,,,,,,,,,,,,,,,,,,95.1618767
,2121359.72,100.1916313,9999.475,,,0.00239644907085402,6.22730144452971E-5,,,,,,,,,5,125,0,6.73399963416159,0.0755307589122187,5.11658912546052E-5,4374,0,100.0784607,100.3048019,9999.475,9999.475,-0.0394975186141755,103.4221,,,,,,,,,,,,,,,,,,,,,,,100.1916313
,2121510.87,105.180706,9999.475,,,0.00232363722662041,5.90380191614522E-5,,,,,,,,,5,125,0,6.99999975040555,0.0755307589122187,5.05223556033551E-5,4374,0,105.0711441,105.2902679,9999.475,9999.475,-0.0313795787899765,108.58195,,,,,,,,,,,,,,,,,,,,,,,105.180706
,2121662.73,110.18368145,9999.475,,,0.00228096164603831,6.27441963392481E-5,,,,,,,,,5,125,0,6.84299999848008,0.0755307589122187,5.04374913890565E-5,4374,0,110.0670242,110.3003387,9999.475,9999.475,-0.0470381255222652,113.8426,,,,,,,,,,,,,,,,,,,,,,,110.18368145
,2121813.93,115.1651955,9999.475,,,0.00222058054497473,6.31284357875808E-5,,,,,,,,,5,125,0,6.92200027406216,0.0755307589122187,5.00512512657142E-5,4374,0,115.0558167,115.2745743,9999.475,9999.475,-0.0467797439213366,119.07475,,,,,,,,,,,,,,,,,,,,,,,115.1651955
,2121965.34,120.1517296,9999.475,,,0.00215705335111574,6.27166821463351E-5,,,,,,,,,5,125,0,6.99999975040555,0.0755307589122187,4.99433815769184E-5,4374,0,120.0367279,120.2667313,9999.475,9999.475,-0.0351622320505617,124.33765,,,,,,,,,,,,,,,,,,,,,,,120.1517296
,2122116.96,125.16456985,9999.475,,,0.00209687602267166,6.20859685866254E-5,,,,,,,,,5,125,0,6.39000004157424,0.0755307589122187,4.9417843372956E-5,4374,0,125.060051,125.2690887,9999.475,9999.475,-0.0314242551506729,129.50745,,,,,,,,,,,,,,,,,,,,,,,125.16456985
,2122269.38,130.18667605,9999.475,,,0.0020600619546137,6.34705063133773E-5,,,,,,,,,5,125,0,6.92199964541942,0.0755307589122187,4.90358027414169E-5,4374,0,130.0703583,130.3029938,9999.475,9999.475,-0.0351346507478179,134.7727,,,,,,,,,,,,,,,,,,,,,,,130.18667605
,2122420.24,135.17184445,9999.475,,,0.00200423285728094,6.32209356244879E-5,,,,,,,,,5,125,0,7.1400003740564,0.0755307589122187,4.87292496040519E-5,4374,0,135.0485687,135.2951202,9999.475,9999.475,-0.032552012870584,140.0771,,,,,,,,,,,,,,,,,,,,,,,135.17184445
,2122570.21,140.1567459,9999.475,,,0.00196565852495494,6.55408549365358E-5,,,,,,,,,5,125,0,6.73400026280433,0.0755307589122187,4.84935863380741E-5,4374,0,140.0470123,140.2664795,9999.475,9999.475,-0.0376440788195099,145.0055,,,,,,,,,,,,,,,,,,,,,,,140.1567459
,2122723.36,145.1427536,9999.475,,,0.00192004957136554,6.41496446701907E-5,,,,,,,,,5,125,0,6.7810001084581,0.0755307589122187,4.83256154656527E-5,4374,0,145.0287018,145.2568054,9999.475,9999.475,-0.0341700837037621,151.05715,,,,,,,,,,,,,,,,,,,,,,,145.1427536
,2122873.34,150.16130065,9999.475,,,0.00186851288532048,6.62174731732827E-5,,,,,,,,,5,125,0,7.17200017534196,0.0755307589122187,4.79440371827976E-5,4374,0,150.042984,150.2796173,9999.475,9999.475,-0.0333909256942561,155.1537,,,,,,,,,,,,,,,,,,,,,,,150.16130065
,2123026.13,155.1201019,9999.475,,,0.00183201914899079,6.58094614247337E-5,,,,,,,,,5,125,0,6.32800015155226,0.0755307589122187,4.76524317933606E-5,4374,0,155.0088348,155.231369,9999.475,9999.475,-0.0301956067172419,161.93535,,,,,,,,,,,,,,,,,,,,,,,155.1201019
,2123174.38,160.16680145,9999.475,,,0.00178851349159377,6.48753721586097E-5,,,,,,,,,5,125,0,6.8910000147298,0.0755307589122187,4.72095130968405E-5,4374,0,160.0553741,160.2782288,9999.475,9999.475,-0.0278195988526293,164.7794,,,,,,,,,,,,,,,,,,,,,,,160.16680145
,2123330.82,165.15126035,9999.475,,,0.00175741772526785,6.64198601635316E-5,,,,,,,,,5,125,0,6.70300000347197,0.0755307589122187,4.71817854433522E-5,4374,0,165.0422821,165.2602386,9999.475,9999.475,-0.0305133232089491,172.41915,,,,,,,,,,,,,,,,,,,,,,,165.15126035
,2123478.66,170.18476865,9999.475,,,0.00172837410850829,7.02969494094444E-5,,,,,,,,,5,125,0,6.70300000347197,0.0755307589122187,4.70303557390065E-5,4374,0,170.0582733,170.311264,9999.475,9999.475,-0.0447436633089671,176.1971,,,,,,,,,,,,,,,,,,,,,,,170.18476865
,2123628.75,175.11689755,9999.475,,,0.0016783108785716,6.87954743503178E-5,,,,,,,,,5,125,0,6.95300053339452,0.0755307589122187,4.66884715858741E-5,4374,0,175.0223846,175.2114105,9999.475,9999.475,-0.0359763438728953,179.72365,,,,,,,,,,,,,,,,,,,,,,,175.11689755
,2123790.15,180.18038175,9999.475,,,0.00165155155692834,6.55640315643417E-5,,,,,,,,,5,125,0,7.20299980603159,0.0755307589122187,4.62775898462897E-5,4374,0,180.0418701,180.3188934,9999.475,9999.475,-0.0262001896872119,190.8042,,,,,,,,,,,,,,,,,,,,,,,180.18038175
,2123935.92,185.24046325,9999.475,,,0.00158896644206118,7.28369809944349E-5,,,,,,,,,5,125,0,7.15599996037781,0.0755307589122187,4.65023978466732E-5,4374,0,185.0817566,185.3991699,9999.475,9999.475,0.0420287421534094,192.3367,,,,,,,,,,,,,,,,,,,,,,,185.24046325
,2124081.49,190.1887436,9999.475,,,0.00156540611353458,6.94293347096145E-5,,,,,,,,,5,125,0,6.99999975040555,0.0755307589122187,4.63588543924675E-5,4374,0,190.0776215,190.2998657,9999.475,9999.475,-0.0278752616524636,194.66865,,,,,,,,,,,,,,,,,,,,,,,190.1887436
,2124234.72,195.1160126,9999.475,,,0.00154379088742698,7.06054987532445E-5,,,,,,,,,5,125,0,6.93699968978763,0.0755307589122187,4.64958934659066E-5,4374,0,195.0283661,195.2036591,9999.475,9999.475,-0.0242814326380829,199.39705,,,,,,,,,,,,,,,,,,,,,,,195.1160126
,2124397.15,200.1960144,9999.475,,,0.00152968996134926,7.02616055953946E-5,,,,,,,,,5,125,0,6.65599952917546,0.0755307589122187,4.62582493882903E-5,4374,0,200.1088867,200.2831421,9999.475,9999.475,-0.0285663314465653,210.0722,,,,,,,,,,,,,,,,,,,,,,,200.1960144
,2124549.59,205.18343355,9999.475,,,0.00148839469357078,7.30697194709502E-5,,,,,,,,,5,125,0,6.96799994911998,0.0755307589122187,4.61487270692927E-5,4374,0,205.0427094,205.3241577,9999.475,9999.475,-0.0322076530549532,218.2795,,,,,,,,,,,,,,,,,,,,,,,205.18343355
,2124696.96,210.2093277,9999.475,,,0.00145632105292165,7.77690456702913E-5,,,,,,,,,5,125,0,6.62499989848584,0.0755307589122187,4.59679936564296E-5,4374,0,210.0505676,210.3680878,9999.475,9999.475,-0.0391327477388298,220.69355,,,,,,,,,,,,,,,,,,,,,,,210.2093277
,2124845.80,215.24505615,9999.475,,,0.00142463815077386,7.8517301656846E-5,,,,,,,,,5,125,0,6.71900021843612,0.0755307589122187,4.57850350971546E-5,4374,0,215.067749,215.4223633,9999.475,9999.475,-0.0409890711732899,223.9898,,,,,,,,,,,,,,,,,,,,,,,215.24505615
,2124994.72,220.21772765,9999.475,,,0.00140292725568079,7.64498439275171E-5,,,,,,,,,5,125,0,6.95299990475178,0.0755307589122187,4.58084791267917E-5,4374,0,220.0418243,220.393631,9999.475,9999.475,-0.0366103013492606,228.51005,,,,,,,,,,,,,,,,,,,,,,,220.21772765
,2125147.03,225.23230745,9999.475,,,0.00136383292830623,8.19287914838472E-5,,,,,,,,,5,125,0,6.92200027406216,0.0755307589122187,4.55963036840401E-5,4374,0,225.0615082,225.4031067,9999.475,9999.475,-0.0478602093411107,233.3766,,,,,,,,,,,,,,,,,,,,,,,225.23230745
,2125299.22,230.2660141,9999.475,,,0.00134585016003921,8.24888425021106E-5,,,,,,,,,5,125,0,7.07799985539168,0.0755307589122187,4.55990417130975E-5,4374,0,230.0907135,230.4413147,9999.475,9999.475,-0.0435611351330323,238.46745,,,,,,,,,,,,,,,,,,,,,,,230.2660141
,2125452.15,235.24465175,9999.475,,,0.0013376504511745,7.81932636668345E-5,,,,,,,,,5,125,0,6.6560001578182,0.0755307589122187,4.53022359547288E-5,4374,0,235.0641479,235.4251556,9999.475,9999.475,-0.0385710454840919,243.94935,,,,,,,,,,,,,,,,,,,,,,,235.24465175
,2125604.44,240.2220688,9999.475,,,0.00130627218478864,8.1338657225667E-5,,,,,,,,,5,125,0,6.85999975539744,0.0755307589122187,4.53108313354031E-5,4374,0,240.0272522,240.4168854,9999.475,9999.475,-0.0502387058542477,249.4648,,,,,,,,,,,,,,,,,,,,,,,240.2220688
,2125758.91,245.26883695,9999.475,,,0.00127272806649485,8.36743050039149E-5,,,,,,,,,5,125,0,6.67199974413961,0.0755307589122187,4.51376667626167E-5,4374,0,245.099411,245.4382629,9999.475,9999.475,-0.0482164091300076,255.1901,,,,,,,,,,,,,,,,,,,,,,,245.26883695
,2125910.36,250.2587433,9999.475,,,0.00124021594033955,8.42899507960754E-5,,,,,,,,,5,125,0,6.82799995411187,0.0755307589122187,4.48203671035364E-5,4374,0,250.0990906,250.418396,9999.475,9999.475,-0.0515188215405718,260.565,,,,,,,,,,,,,,,,,,,,,,,250.2587433
,2126061.12,255.22034455,9999.475,,,0.00123479024151939,8.89966469945486E-5,,,,,,,,,5,125,0,6.43800005782396,0.0755307589122187,4.45400603116601E-5,4374,0,255.0793762,255.3613129,9999.475,9999.475,-0.0539498745089119,266.25065,,,,,,,,,,,,,,,,,,,,,,,255.22034455
,2126211.38,260.20669555,9999.475,,,0.00120599176527744,8.43629040874798E-5,,,,,,,,,5,125,0,6.73499980475754,0.0755307589122187,4.37978292883987E-5,4374,0,260.0744934,260.3388977,9999.475,9999.475,-0.0464863837219992,271.5194,,,,,,,,,,,,,,,,,,,,,,,260.20669555
,2126358.88,265.1421661,9999.475,,,0.00119404123986173,8.53387091149424E-5,,,,,,,,,5,125,0,6.54700042214245,0.0755307589122187,4.36738993109468E-5,4374,0,265.0207214,265.2636108,9999.475,9999.475,-0.0449940840676567,276.85615,,,,,,,,,,,,,,,,,,,,,,,265.1421661
,2126511.18,270.18540955,9999.475,,,0.0011791549361005,8.59367973288461E-5,,,,,,,,,5,125,0,6.56200046651065,0.0755307589122187,4.3445157025942E-5,4374,0,270.0627747,270.3080444,9999.475,9999.475,-0.0539614397741785,281.89775,,,,,,,,,,,,,,,,,,,,,,,270.18540955
,2126661.33,275.16264345,9999.475,,,0.00115792659699996,8.90739798157482E-5,,,,,,,,,5,125,0,6.70300000347197,0.0755307589122187,4.30647103435449E-5,4374,0,275.0391541,275.2861328,9999.475,9999.475,-0.0598602340635372,286.45345,,,,,,,,,,,,,,,,,,,,,,,275.16264345
,2126812.80,280.1818848,9999.475,,,0.00111913127560674,9.20330740448951E-5,,,,,,,,,5,125,0,7.13999974541366,0.0755307589122187,4.29445354331846E-5,4374,0,280.0666199,280.2971497,9999.475,9999.475,-0.062515906989674,291.5804,,,,,,,,,,,,,,,,,,,,,,,280.1818848
,2126964.59,285.19987485,9999.475,,,0.00110707784794529,9.44800205558115E-5,,,,,,,,,5,125,0,6.48400036152452,0.0755307589122187,4.26711145167839E-5,4374,0,285.0894775,285.3102722,9999.475,9999.475,-0.0600519006965554,295.9935,,,,,,,,,,,,,,,,,,,,,,,285.19987485
,2127115.70,290.178833,9999.475,,,0.00110049498861583,9.93645768238411E-5,,,,,,,,,5,125,0,6.85900021344423,0.0755307589122187,4.25486019605531E-5,4374,0,290.0486755,290.3089905,9999.475,9999.475,-0.0765309545122969,300.8133,,,,,,,,,,,,,,,,,,,,,,,290.178833
,2127270.79,295.13949585,9999.475,,,0.00108422489514318,0.000104135276025069,,,,,,,,,5,125,0,6.65599952917546,0.0755307589122187,4.23524803353898E-5,4374,0,295.0129395,295.2660522,9999.475,9999.475,-0.0893260390602661,306.83505,,,,,,,,,,,,,,,,,,,,,,,295.13949585
,2127444.78,300.03468325,9999.475,,,0.00107542456784139,0.000112182295446597,,,,,,,,,5,125,0,6.90600005909801,0.0755307589122187,4.82505962491018E-5,4373,0,299.9817505,300.087616,9999.475,9999.475,-0.121235946431496,297.91545,,,,,,,,,,,,,,,,,,,,,,,300.03468325